<?xml version="1.0" ?>
<robot name="final_project" xmlns:xacro="http://www.ros.org/wiki/xacro">

<xacro:include filename="$(find final_project_description)/urdf/materials.xacro" />
<xacro:include filename="$(find final_project_description)/urdf/final_project.gazebo" />

<!-- Properties -->
<xacro:property name="wheel_radius" value="0.0325"/>
<xacro:property name="wheel_width" value="0.02"/>
<xacro:property name="wheel_separation" value="0.1"/>
<xacro:property name="wheel_base" value="0.09"/>

<xacro:property name="base_length" value="0.18"/>
<xacro:property name="base_width" value="0.10"/>
<xacro:property name="base_height" value="0.08"/>
<xacro:property name="base_mass" value="2.0"/>  <!-- INCREASED from 1 -->
<xacro:property name="wheel_mass" value="0.3"/>  <!-- INCREASED from 0.2 -->

<!-- Base Footprint -->
<link name="base_footprint"/>

<!-- Base Link -->
<link name="base_link">
  <inertial>
    <origin xyz="0 0 0" rpy="0 0 0"/>
    <mass value="${base_mass}"/>
    <inertia
      ixx="${(1/12) * base_mass * (base_width*base_width + base_height*base_height)}" 
      ixy="0.0" ixz="0.0"
      iyy="${(1/12) * base_mass * (base_length*base_length + base_height*base_height)}" 
      iyz="0.0"
      izz="${(1/12) * base_mass * (base_length*base_length + base_width*base_width)}"/>
  </inertial>
  <visual>
    <origin xyz="0 0 0" rpy="0 0 0"/>
    <geometry>
      <mesh filename="file://$(find final_project_description)/meshes/base_link.stl" scale="0.001 0.001 0.001"/>
    </geometry>
    <material name="silver"/>
  </visual>
  <collision>
    <origin xyz="0 0 0" rpy="0 0 0"/>
    <geometry>
      <box size="${base_length} ${base_width} ${base_height}"/>
    </geometry>
  </collision>
</link>

<!-- Joint: base_footprint to base_link -->
<joint name="base_footprint_joint" type="fixed">
  <parent link="base_footprint"/>
  <child link="base_link"/>
  <origin xyz="0 0 0" rpy="0 0 0"/>
</joint>

<!-- Wheel Macro -->
<xacro:macro name="wheel" params="prefix side x_reflect y_reflect">
  <link name="${prefix}_${side}_wheel_1">
    <inertial>
      <origin xyz="0 0 0" rpy="0 0 0"/>
      <mass value="${wheel_mass}"/>
      <inertia
        ixx="${(wheel_mass/12.0) * (3*wheel_radius*wheel_radius + wheel_width*wheel_width)}" 
        ixy="0" ixz="0"
        iyy="${(wheel_mass/2.0) * (wheel_radius*wheel_radius)}" 
        iyz="0"
        izz="${(wheel_mass/12.0) * (3*wheel_radius*wheel_radius + wheel_width*wheel_width)}"/>
    </inertial>
    <!-- Use cylinder for consistent visualization -->
    <visual>
      <origin xyz="0 0 0" rpy="1.5708 0 0"/>
      <geometry>
        <cylinder radius="${wheel_radius}" length="${wheel_width}"/>
      </geometry>
      <material name="black">
        <color rgba="0 0 0 1"/>
      </material>
    </visual>
    <collision>
      <origin xyz="0 0 0" rpy="1.5708 0 0"/>
      <geometry>
        <cylinder radius="${wheel_radius}" length="${wheel_width}"/>
      </geometry>
    </collision>
  </link>

  <joint name="${prefix}_${side}_wheel_joint" type="continuous">
    <parent link="base_link"/>
    <child link="${prefix}_${side}_wheel_1"/>
    <!-- Wheels positioned close to body -->
    <origin xyz="${x_reflect*wheel_base/2} ${y_reflect*wheel_separation/2} ${-wheel_radius}" rpy="0 0 0"/>
    <axis xyz="0 1 0"/>
    <dynamics damping="0.1" friction="0.1"/>  <!-- Added dynamics -->
  </joint>
</xacro:macro>

<!-- Instantiate Wheels -->
<xacro:wheel prefix="front" side="left" x_reflect="1" y_reflect="1"/>
<xacro:wheel prefix="front" side="right" x_reflect="1" y_reflect="-1"/>
<xacro:wheel prefix="back" side="left" x_reflect="-1" y_reflect="1"/>
<xacro:wheel prefix="back" side="right" x_reflect="-1" y_reflect="-1"/>

<!-- Candy -->
<link name="candy_1">
  <inertial>
    <origin xyz="0 0 0.005" rpy="0 0 0"/>
    <mass value="0.01"/>
    <inertia ixx="0.0001" iyy="0.0001" izz="0.0001" ixy="0.0" iyz="0.0" ixz="0.0"/>
  </inertial>
  <visual>
    <origin xyz="0 0 0" rpy="0 0 0"/>
    <geometry>
      <box size="0.015 0.015 0.01"/>
    </geometry>
    <material name="red">
      <color rgba="1 0 0 1"/>
    </material>
  </visual>
  <collision>
    <origin xyz="0 0 0.005" rpy="0 0 0"/>
    <geometry>
      <box size="0.015 0.015 0.01"/>
    </geometry>
  </collision>
</link>

<!-- LiDAR -->
<link name="lidar_1">
  <inertial>
    <origin xyz="0 0 0.015" rpy="0 0 0"/>
    <mass value="0.1"/>
    <inertia ixx="0.0001" iyy="0.0001" izz="0.0001" ixy="0.0" iyz="0.0" ixz="0.0"/>
  </inertial>
  <visual>
    <origin xyz="0 0 0" rpy="0 0 0"/>
    <geometry>
      <cylinder radius="0.02" length="0.03"/>
    </geometry>
    <material name="blue">
      <color rgba="0 0 1 1"/>
    </material>
  </visual>
  <collision>
    <origin xyz="0 0 0.015" rpy="0 0 0"/>
    <geometry>
      <cylinder radius="0.02" length="0.03"/>
    </geometry>
  </collision>
</link>

<!-- Camera -->
<link name="camera_1">
  <inertial>
    <origin xyz="0.0025 0 0" rpy="0 0 0"/>
    <mass value="0.05"/>
    <inertia ixx="0.0001" iyy="0.0001" izz="0.0001" ixy="0.0" iyz="0.0" ixz="0.0"/>
  </inertial>
  <visual>
    <origin xyz="0 0 0" rpy="0 0 0"/>
    <geometry>
      <box size="0.01 0.03 0.02"/>
    </geometry>
    <material name="green">
      <color rgba="0 1 0 1"/>
    </material>
  </visual>
  <collision>
    <origin xyz="0.0025 0 0" rpy="0 0 0"/>
    <geometry>
      <box size="0.01 0.03 0.02"/>
    </geometry>
  </collision>
</link>

<!-- Camera Optical Frame -->
<link name="camera_optical_link"/>

<!-- Fixed Joints -->
<joint name="candy_joint" type="fixed">
  <origin xyz="-0.04 0.0 0.04" rpy="0 0 0"/>
  <parent link="base_link"/>
  <child link="candy_1"/>
</joint>

<joint name="lidar_joint" type="fixed">
  <origin xyz="0.045 0.0 0.045" rpy="0 0 0"/>
  <parent link="base_link"/>
  <child link="lidar_1"/>
</joint>

<joint name="camera_joint" type="fixed">
  <origin xyz="0.09 0.0 0.04" rpy="0 0 0"/>
  <parent link="base_link"/>
  <child link="camera_1"/>
</joint>

<joint name="camera_optical_joint" type="fixed">
  <origin xyz="0 0 0" rpy="-1.5708 0 -1.5708"/>
  <parent link="camera_1"/>
  <child link="camera_optical_link"/>
</joint>

</robot>
